<?xml version="1.0"?>
<robot name="moving_face" xmlns:xacro="http://www.ros.org/wiki/xacro">

  <!-- ====================== -->
  <!-- BASE LINK (main cube)  -->
  <!-- ====================== -->
  <link name="base_link">
    <visual>
      <origin xyz="0 0 0.15" rpy="0 0 0"/>
      <geometry>
        <box size="0.02 0.2 0.2"/>
      </geometry>
      <material name="blue">
        <color rgba="0 0 1 1"/>
      </material>
    </visual>

    <collision>
      <origin xyz="0 0 0.1" rpy="0 0 0"/>
      <geometry>
        <box size="0.02 0.2 0.2"/>
      </geometry>
    </collision>

    <inertial>
      <origin xyz="0 0 0.15" rpy="0 0 0"/>
      <mass value="1.0"/>
      <inertia ixx="0.01" iyy="0.01" izz="0.01"
               ixy="0" ixz="0" iyz="0"/>
    </inertial>
  </link>

  <!-- ====================== -->
  <!-- LEFT WHEEL             -->
  <!-- ====================== -->
  <link name="left_wheel_link">
    <visual>
      <origin xyz="0 0 0" rpy="1.57 0 0"/>
      <geometry>
        <cylinder length="0.02" radius="0.05"/>
      </geometry>
      <material name= "black-left"><color rgba="0.2 0.2 0.2 1"/></material>
    </visual>

    <collision>
      <origin xyz="0 0 0" rpy="1.57 0 0"/>
      <geometry>
        <cylinder length="0.02" radius="0.05"/>
      </geometry>
    </collision>

    <inertial>
      <origin xyz="0 0 0" rpy="0 0 0"/>
      <mass value="0.1"/>
      <inertia ixx="1e-4" iyy="1e-4" izz="1e-4" ixy="0" ixz="0" iyz="0"/>
    </inertial>
  </link>

  <joint name="left_wheel_joint" type="continuous">
    <parent link="base_link"/>
    <child link="left_wheel_link"/>
    <origin xyz="0 0.11 0.05" rpy="0 0 0"/>
    <axis xyz="0 1 0"/>
  </joint>

  <!-- ====================== -->
  <!-- RIGHT WHEEL            -->
  <!-- ====================== -->
  <link name="right_wheel_link">
    <visual>
      <origin xyz="0 0 0" rpy="1.57 0 0"/>
      <geometry>
        <cylinder length="0.02" radius="0.05"/>
      </geometry>
      <material name= "black-right"><color rgba="0.2 0.2 0.2 1"/></material>
    </visual>

    <collision>
      <origin xyz="0 0 0" rpy="1.57 0 0"/>
      <geometry>
        <cylinder length="0.02" radius="0.05"/>
      </geometry>
    </collision>

    <inertial>
      <origin xyz="0 0 0" rpy="0 0 0"/>
      <mass value="0.1"/>
      <inertia ixx="1e-4" iyy="1e-4" izz="1e-4" ixy="0" ixz="0" iyz="0"/>
    </inertial>
  </link>

  <joint name="right_wheel_joint" type="continuous">
    <parent link="base_link"/>
    <child link="right_wheel_link"/>
    <origin xyz="0 -0.11 0.05" rpy="0 0 0"/>
    <axis xyz="0 1 0"/>
  </joint>

  <!-- ====================== -->
  <!-- GAZEBO DIFF DRIVE      -->
  <!-- ====================== -->

  <gazebo>
    <plugin name="diff_drive" filename="libgazebo_ros_diff_drive.so">
      <ros>
        <namespace>/target</namespace>
        <remapping>cmd_vel:=cmd_vel</remapping>
      </ros>

      <left_joint>left_wheel_joint</left_joint>
      <right_joint>right_wheel_joint</right_joint>

      <wheel_separation>0.2</wheel_separation>
      <wheel_diameter>0.10</wheel_diameter>

      <command_topic>cmd_vel</command_topic>
      <odometry_topic>odom</odometry_topic>
      <robot_base_frame>base_link</robot_base_frame>

      <update_rate>50</update_rate>
    </plugin>
  </gazebo>

</robot>
