<?xml version="1.0"?>
<robot name="moving_face">

  <link name="lil_cube">

    <visual>
      <origin xyz="0 0 0" rpy="0 0 0"/>
      <geometry>
        <box size="0.01 0.01 0.01"/>
      </geometry>
      <material name="red">
        <color rgba="1 0 0 1"/>
      </material>
    </visual>

    <collision>
      <origin xyz="0 0 0" rpy="0 0 0"/>
      <geometry>
        <box size="0.01 0.01 0.01"/>
      </geometry>
    </collision>

    <inertial>
      <mass value="1.0"/>
      <origin xyz="0 0 0"/>
      <inertia ixx="0.01" ixy="0" ixz="0"
                iyy="0.01" iyz="0"
                izz="0.01"/>
    </inertial>

  </link>

  <!-- A single cube -->
  <link name="cube_link">

    <visual>
      <origin xyz="0 0 0" rpy="0 0 0"/>
      <geometry>
        <box size="0.2 0.2 0.2"/>
      </geometry>
      <material name="blue">
        <color rgba="0 0 1 1"/>
      </material>
    </visual>

    <collision>
      <origin xyz="0 0 0" rpy="0 0 0"/>
      <geometry>
        <box size="0.2 0.2 0.2"/>
      </geometry>
    </collision>

    <inertial>
      <mass value="1.0"/>
      <origin xyz="0 0 0"/>
      <inertia ixx="0.01" ixy="0" ixz="0"
               iyy="0.01" iyz="0"
               izz="0.01"/>
    </inertial>

  </link>

  <joint name="prism_joint" type="prismatic">
      <parent link="lil_cube"/>
      <child link="cube_link"/>
      <origin xyz="0 0 0.05" rpy="0 0 0"/>
      <axis xyz="0 0 1"/>
      <limit lower="-3.14159" upper="3.14159" effort="10" velocity="2.0"/>
      <dynamics damping="0.5" friction="0.1"/>
  </joint>

  <!-- Make lil_cube effectively fixed: no gravity, kinematic -->
  <gazebo reference="lil_cube">
    <gravity>false</gravity>
    <kinematic>true</kinematic>
  </gazebo>

</robot>
